Workbook

Sheet Dashboard
A2: EMPLOYEE SEPARATION ANALYTICS DASHBOARD
A3: Emory Valley Center
A5: CALENDAR YEAR: | B5: FY 2026 | C5: JAN 1 — DEC 31 | F5: EVC FISCAL YEAR: | G5: FY EVC 2026 | H5: JUL 1 — JUN 30
A7: TOTAL ACTIVE EMPLOYEES | D7: YTD SEPARATIONS | G7: TURNOVER RATE | J7: VOLUNTARY %
A8: =VLOOKUP($B$5,Data!$A$2:$K$6,2,FALSE()) -> 366 | D8: =VLOOKUP($B$5,Data!$A$2:$K$6,3,FALSE()) -> 35 | G8: =VLOOKUP($B$5,Data!$A$2:$K$6,4,FALSE()) -> 0.095628415 | J8: =VLOOKUP($B$5,Data!$A$2:$K$6,9,FALSE()) -> 0.6
A9: as of FY start | D9: =VLOOKUP($B$5,Data!$A$2:$K$6,6,FALSE())&" voluntary / "&VLOOKUP($B$5,Data!$A$2:$K$6,7,FALSE())&" involuntary" -> 21 voluntary / 4 involuntary | G9: ="Avg "&TEXT(VLOOKUP($B$5,Data!$A$2:$K$6,5,FALSE()),"0.0")&"/month" -> Avg 8.8/month | J9: ="Rehire eligible: "&TEXT(VLOOKUP($B$5,Data!$A$2:$K$6,10,FALSE()),"0%") -> Rehire eligible: 43%
A11: MONTHLY SEPARATIONS | G11: SEPARATIONS BY JOB
A12: Month | B12: Separations | C12: % of YTD | D12: TOR % | E12: Cumulative | G12: Job Title | H12: Count | I12: % of Total | J12: TOR %
A13: January | B13: =INDEX(Data!$A$11:$M$15,MATCH($B$5,Data!$A$11:$A$15,0),2) -> 8 | C13: =IF(VLOOKUP($B$5,Data!$A$2:$K$6,3,FALSE())=0,0,B13/VLOOKUP($B$5,Data!$A$2:$K$6,3,FALSE())) -> 0.22857143 | D13: =IF(VLOOKUP($B$5,Data!$A$2:$K$6,2,FALSE())=0,0,B13/VLOOKUP($B$5,Data!$A$2:$K$6,2,FALSE())) -> 0.021857923 | E13: =B13 -> 8 | G13: LEADERSHIP
A14: February | B14: =INDEX(Data!$A$11:$M$15,MATCH($B$5,Data!$A$11:$A$15,0),3) -> 10 | C14: =IF(VLOOKUP($B$5,Data!$A$2:$K$6,3,FALSE())=0,0,B14/VLOOKUP($B$5,Data!$A$2:$K$6,3,FALSE())) -> 0.28571429 | D14: =IF(VLOOKUP($B$5,Data!$A$2:$K$6,2,FALSE())=0,0,B14/VLOOKUP($B$5,Data!$A$2:$K$6,2,FALSE())) -> 0.027322404 | E14: =E13+B14 -> 18 | G14: President | H14: =INDEX(Data!$A$21:$F$21,1,MATCH($B$5,Data!$B$20:$F$20,0)+1) -> 0 | I14: =IF(VLOOKUP($B$5,Data!$A$2:$K$6,3,FALSE())=0,0,H14/VLOOKUP($B$5,Data!$A$2:$K$6,3,FALSE())) -> 0 | J14: =IF(VLOOKUP($B$5,Data!$A$2:$K$6,2,FALSE())=0,0,H14/VLOOKUP($B$5,Data!$A$2:$K$6,2,FALSE())) -> 0
A15: March | B15: =INDEX(Data!$A$11:$M$15,MATCH($B$5,Data!$A$11:$A$15,0),4) -> 10 | C15: =IF(VLOOKUP($B$5,Data!$A$2:$K$6,3,FALSE())=0,0,B15/VLOOKUP($B$5,Data!$A$2:$K$6,3,FALSE())) -> 0.28571429 | D15: =IF(VLOOKUP($B$5,Data!$A$2:$K$6,2,FALSE())=0,0,B15/VLOOKUP($B$5,Data!$A$2:$K$6,2,FALSE())) -> 0.027322404 | E15: =E14+B15 -> 28 | G15: VP of Operations | H15: =INDEX(Data!$A$22:$F$22,1,MATCH($B$5,Data!$B$20:$F$20,0)+1) -> 0 | I15: =IF(VLOOKUP($B$5,Data!$A$2:$K$6,3,FALSE())=0,0,H15/VLOOKUP($B$5,Data!$A$2:$K$6,3,FALSE())) -> 0 | J15: =IF(VLOOKUP($B$5,Data!$A$2:$K$6,2,FALSE())=0,0,H15/VLOOKUP($B$5,Data!$A$2:$K$6,2,FALSE())) -> 0
A16: April | B16: =INDEX(Data!$A$11:$M$15,MATCH($B$5,Data!$A$11:$A$15,0),5) -> 7 | C16: =IF(VLOOKUP($B$5,Data!$A$2:$K$6,3,FALSE())=0,0,B16/VLOOKUP($B$5,Data!$A$2:$K$6,3,FALSE())) -> 0.2 | D16: =IF(VLOOKUP($B$5,Data!$A$2:$K$6,2,FALSE())=0,0,B16/VLOOKUP($B$5,Data!$A$2:$K$6,2,FALSE())) -> 0.019125683 | E16: =E15+B16 -> 35 | G16: VP of Children Services | H16: =INDEX(Data!$A$23:$F$23,1,MATCH($B$5,Data!$B$20:$F$20,0)+1) -> 0 | I16: =IF(VLOOKUP($B$5,Data!$A$2:$K$6,3,FALSE())=0,0,H16/VLOOKUP($B$5,Data!$A$2:$K$6,3,FALSE())) -> 0 | J16: =IF(VLOOKUP($B$5,Data!$A$2:$K$6,2,FALSE())=0,0,H16/VLOOKUP($B$5,Data!$A$2:$K$6,2,FALSE())) -> 0
A17: May | B17: =INDEX(Data!$A$11:$M$15,MATCH($B$5,Data!$A$11:$A$15,0),6) -> 0 | C17: =IF(VLOOKUP($B$5,Data!$A$2:$K$6,3,FALSE())=0,0,B17/VLOOKUP($B$5,Data!$A$2:$K$6,3,FALSE())) -> 0 | D17: =IF(VLOOKUP($B$5,Data!$A$2:$K$6,2,FALSE())=0,0,B17/VLOOKUP($B$5,Data!$A$2:$K$6,2,FALSE())) -> 0 | E17: =E16+B17 -> 35 | G17: VP of Professional Services | H17: =INDEX(Data!$A$24:$F$24,1,MATCH($B$5,Data!$B$20:$F$20,0)+1) -> 0 | I17: =IF(VLOOKUP($B$5,Data!$A$2:$K$6,3,FALSE())=0,0,H17/VLOOKUP($B$5,Data!$A$2:$K$6,3,FALSE())) -> 0 | J17: =IF(VLOOKUP($B$5,Data!$A$2:$K$6,2,FALSE())=0,0,H17/VLOOKUP($B$5,Data!$A$2:$K$6,2,FALSE())) -> 0
A18: June | B18: =INDEX(Data!$A$11:$M$15,MATCH($B$5,Data!$A$11:$A$15,0),7) -> 0 | C18: =IF(VLOOKUP($B$5,Data!$A$2:$K$6,3,FALSE())=0,0,B18/VLOOKUP($B$5,Data!$A$2:$K$6,3,FALSE())) -> 0 | D18: =IF(VLOOKUP($B$5,Data!$A$2:$K$6,2,FALSE())=0,0,B18/VLOOKUP($B$5,Data!$A$2:$K$6,2,FALSE())) -> 0 | E18: =E17+B18 -> 35 | G18: VP of Behavioral Health | H18: =INDEX(Data!$A$25:$F$25,1,MATCH($B$5,Data!$B$20:$F$20,0)+1) -> 0 | I18: =IF(VLOOKUP($B$5,Data!$A$2:$K$6,3,FALSE())=0,0,H18/VLOOKUP($B$5,Data!$A$2:$K$6,3,FALSE())) -> 0 | J18: =IF(VLOOKUP($B$5,Data!$A$2:$K$6,2,FALSE())=0,0,H18/VLOOKUP($B$5,Data!$A$2:$K$6,2,FALSE())) -> 0
A19: July | B19: =INDEX(Data!$A$11:$M$15,MATCH($B$5,Data!$A$11:$A$15,0),8) -> 0 | C19: =IF(VLOOKUP($B$5,Data!$A$2:$K$6,3,FALSE())=0,0,B19/VLOOKUP($B$5,Data!$A$2:$K$6,3,FALSE())) -> 0 | D19: =IF(VLOOKUP($B$5,Data!$A$2:$K$6,2,FALSE())=0,0,B19/VLOOKUP($B$5,Data!$A$2:$K$6,2,FALSE())) -> 0 | E19: =E18+B19 -> 35 | G19: VP of Human Resources | H19: =INDEX(Data!$A$26:$F$26,1,MATCH($B$5,Data!$B$20:$F$20,0)+1) -> 0 | I19: =IF(VLOOKUP($B$5,Data!$A$2:$K$6,3,FALSE())=0,0,H19/VLOOKUP($B$5,Data!$A$2:$K$6,3,FALSE())) -> 0 | J19: =IF(VLOOKUP($B$5,Data!$A$2:$K$6,2,FALSE())=0,0,H19/VLOOKUP($B$5,Data!$A$2:$K$6,2,FALSE())) -> 0
A20: August | B20: =INDEX(Data!$A$11:$M$15,MATCH($B$5,Data!$A$11:$A$15,0),9) -> 0 | C20: =IF(VLOOKUP($B$5,Data!$A$2:$K$6,3,FALSE())=0,0,B20/VLOOKUP($B$5,Data!$A$2:$K$6,3,FALSE())) -> 0 | D20: =IF(VLOOKUP($B$5,Data!$A$2:$K$6,2,FALSE())=0,0,B20/VLOOKUP($B$5,Data!$A$2:$K$6,2,FALSE())) -> 0 | E20: =E19+B20 -> 35 | G20: VP of Employment Services | H20: =INDEX(Data!$A$27:$F$27,1,MATCH($B$5,Data!$B$20:$F$20,0)+1) -> 0 | I20: =IF(VLOOKUP($B$5,Data!$A$2:$K$6,3,FALSE())=0,0,H20/VLOOKUP($B$5,Data!$A$2:$K$6,3,FALSE())) -> 0 | J20: =IF(VLOOKUP($B$5,Data!$A$2:$K$6,2,FALSE())=0,0,H20/VLOOKUP($B$5,Data!$A$2:$K$6,2,FALSE())) -> 0
A21: September | B21: =INDEX(Data!$A$11:$M$15,MATCH($B$5,Data!$A$11:$A$15,0),10) -> 0 | C21: =IF(VLOOKUP($B$5,Data!$A$2:$K$6,3,FALSE())=0,0,B21/VLOOKUP($B$5,Data!$A$2:$K$6,3,FALSE())) -> 0 | D21: =IF(VLOOKUP($B$5,Data!$A$2:$K$6,2,FALSE())=0,0,B21/VLOOKUP($B$5,Data!$A$2:$K$6,2,FALSE())) -> 0 | E21: =E20+B21 -> 35 | G21: VP of Family Support | H21: =INDEX(Data!$A$28:$F$28,1,MATCH($B$5,Data!$B$20:$F$20,0)+1) -> 0 | I21: =IF(VLOOKUP($B$5,Data!$A$2:$K$6,3,FALSE())=0,0,H21/VLOOKUP($B$5,Data!$A$2:$K$6,3,FALSE())) -> 0 | J21: =IF(VLOOKUP($B$5,Data!$A$2:$K$6,2,FALSE())=0,0,H21/VLOOKUP($B$5,Data!$A$2:$K$6,2,FALSE())) -> 0
A22: October | B22: =INDEX(Data!$A$11:$M$15,MATCH($B$5,Data!$A$11:$A$15,0),11) -> 0 | C22: =IF(VLOOKUP($B$5,Data!$A$2:$K$6,3,FALSE())=0,0,B22/VLOOKUP($B$5,Data!$A$2:$K$6,3,FALSE())) -> 0 | D22: =IF(VLOOKUP($B$5,Data!$A$2:$K$6,2,FALSE())=0,0,B22/VLOOKUP($B$5,Data!$A$2:$K$6,2,FALSE())) -> 0 | E22: =E21+B22 -> 35 | G22: VP of Finance | H22: =INDEX(Data!$A$29:$F$29,1,MATCH($B$5,Data!$B$20:$F$20,0)+1) -> 1 | I22: =IF(VLOOKUP($B$5,Data!$A$2:$K$6,3,FALSE())=0,0,H22/VLOOKUP($B$5,Data!$A$2:$K$6,3,FALSE())) -> 0.028571429 | J22: =IF(VLOOKUP($B$5,Data!$A$2:$K$6,2,FALSE())=0,0,H22/VLOOKUP($B$5,Data!$A$2:$K$6,2,FALSE())) -> 0.0027322404
A23: November | B23: =INDEX(Data!$A$11:$M$15,MATCH($B$5,Data!$A$11:$A$15,0),12) -> 0 | C23: =IF(VLOOKUP($B$5,Data!$A$2:$K$6,3,FALSE())=0,0,B23/VLOOKUP($B$5,Data!$A$2:$K$6,3,FALSE())) -> 0 | D23: =IF(VLOOKUP($B$5,Data!$A$2:$K$6,2,FALSE())=0,0,B23/VLOOKUP($B$5,Data!$A$2:$K$6,2,FALSE())) -> 0 | E23: =E22+B23 -> 35 | G23: Director of Operations | H23: =INDEX(Data!$A$30:$F$30,1,MATCH($B$5,Data!$B$20:$F$20,0)+1) -> 0 | I23: =IF(VLOOKUP($B$5,Data!$A$2:$K$6,3,FALSE())=0,0,H23/VLOOKUP($B$5,Data!$A$2:$K$6,3,FALSE())) -> 0 | J23: =IF(VLOOKUP($B$5,Data!$A$2:$K$6,2,FALSE())=0,0,H23/VLOOKUP($B$5,Data!$A$2:$K$6,2,FALSE())) -> 0
A24: December | B24: =INDEX(Data!$A$11:$M$15,MATCH($B$5,Data!$A$11:$A$15,0),13) -> 0 | C24: =IF(VLOOKUP($B$5,Data!$A$2:$K$6,3,FALSE())=0,0,B24/VLOOKUP($B$5,Data!$A$2:$K$6,3,FALSE())) -> 0 | D24: =IF(VLOOKUP($B$5,Data!$A$2:$K$6,2,FALSE())=0,0,B24/VLOOKUP($B$5,Data!$A$2:$K$6,2,FALSE())) -> 0 | E24: =E23+B24 -> 35 | G24: Director of Children Services | H24: =INDEX(Data!$A$31:$F$31,1,MATCH($B$5,Data!$B$20:$F$20,0)+1) -> 0 | I24: =IF(VLOOKUP($B$5,Data!$A$2:$K$6,3,FALSE())=0,0,H24/VLOOKUP($B$5,Data!$A$2:$K$6,3,FALSE())) -> 0 | J24: =IF(VLOOKUP($B$5,Data!$A$2:$K$6,2,FALSE())=0,0,H24/VLOOKUP($B$5,Data!$A$2:$K$6,2,FALSE())) -> 0
G25: Director of Professional Services | H25: =INDEX(Data!$A$32:$F$32,1,MATCH($B$5,Data!$B$20:$F$20,0)+1) -> 0 | I25: =IF(VLOOKUP($B$5,Data!$A$2:$K$6,3,FALSE())=0,0,H25/VLOOKUP($B$5,Data!$A$2:$K$6,3,FALSE())) -> 0 | J25: =IF(VLOOKUP($B$5,Data!$A$2:$K$6,2,FALSE())=0,0,H25/VLOOKUP($B$5,Data!$A$2:$K$6,2,FALSE())) -> 0
A26: SEPARATIONS BY REASON | G26: Director of Behavioral Health | H26: =INDEX(Data!$A$33:$F$33,1,MATCH($B$5,Data!$B$20:$F$20,0)+1) -> 0 | I26: =IF(VLOOKUP($B$5,Data!$A$2:$K$6,3,FALSE())=0,0,H26/VLOOKUP($B$5,Data!$A$2:$K$6,3,FALSE())) -> 0 | J26: =IF(VLOOKUP($B$5,Data!$A$2:$K$6,2,FALSE())=0,0,H26/VLOOKUP($B$5,Data!$A$2:$K$6,2,FALSE())) -> 0
A27: Reason | B27: Count | C27: % of Total | D27: Category | G27: Director of Human Resources | H27: =INDEX(Data!$A$34:$F$34,1,MATCH($B$5,Data!$B$20:$F$20,0)+1) -> 0 | I27: =IF(VLOOKUP($B$5,Data!$A$2:$K$6,3,FALSE())=0,0,H27/VLOOKUP($B$5,Data!$A$2:$K$6,3,FALSE())) -> 0 | J27: =IF(VLOOKUP($B$5,Data!$A$2:$K$6,2,FALSE())=0,0,H27/VLOOKUP($B$5,Data!$A$2:$K$6,2,FALSE())) -> 0
A28: Resignation | B28: =INDEX(Data!$A$56:$G$56,1,MATCH($B$5,Data!$C$55:$G$55,0)+2) -> 15 | C28: =IF(VLOOKUP($B$5,Data!$A$2:$K$6,3,FALSE())=0,0,B28/VLOOKUP($B$5,Data!$A$2:$K$6,3,FALSE())) -> 0.42857143 | D28: Voluntary | G28: Director of Finance | H28: =INDEX(Data!$A$35:$F$35,1,MATCH($B$5,Data!$B$20:$F$20,0)+1) -> 0 | I28: =IF(VLOOKUP($B$5,Data!$A$2:$K$6,3,FALSE())=0,0,H28/VLOOKUP($B$5,Data!$A$2:$K$6,3,FALSE())) -> 0 | J28: =IF(VLOOKUP($B$5,Data!$A$2:$K$6,2,FALSE())=0,0,H28/VLOOKUP($B$5,Data!$A$2:$K$6,2,FALSE())) -> 0
A29: Better Opportunity | B29: =INDEX(Data!$A$57:$G$57,1,MATCH($B$5,Data!$C$55:$G$55,0)+2) -> 3 | C29: =IF(VLOOKUP($B$5,Data!$A$2:$K$6,3,FALSE())=0,0,B29/VLOOKUP($B$5,Data!$A$2:$K$6,3,FALSE())) -> 0.085714286 | D29: Voluntary | G29: Director of Employment Services | H29: =INDEX(Data!$A$36:$F$36,1,MATCH($B$5,Data!$B$20:$F$20,0)+1) -> 0 | I29: =IF(VLOOKUP($B$5,Data!$A$2:$K$6,3,FALSE())=0,0,H29/VLOOKUP($B$5,Data!$A$2:$K$6,3,FALSE())) -> 0 | J29: =IF(VLOOKUP($B$5,Data!$A$2:$K$6,2,FALSE())=0,0,H29/VLOOKUP($B$5,Data!$A$2:$K$6,2,FALSE())) -> 0
A30: Personal Reasons | B30: =INDEX(Data!$A$58:$G$58,1,MATCH($B$5,Data!$C$55:$G$55,0)+2) -> 3 | C30: =IF(VLOOKUP($B$5,Data!$A$2:$K$6,3,FALSE())=0,0,B30/VLOOKUP($B$5,Data!$A$2:$K$6,3,FALSE())) -> 0.085714286 | D30: Voluntary | G30: Director of Family Support | H30: =INDEX(Data!$A$37:$F$37,1,MATCH($B$5,Data!$B$20:$F$20,0)+1) -> 0 | I30: =IF(VLOOKUP($B$5,Data!$A$2:$K$6,3,FALSE())=0,0,H30/VLOOKUP($B$5,Data!$A$2:$K$6,3,FALSE())) -> 0 | J30: =IF(VLOOKUP($B$5,Data!$A$2:$K$6,2,FALSE())=0,0,H30/VLOOKUP($B$5,Data!$A$2:$K$6,2,FALSE())) -> 0
A31: Relocation | B31: =INDEX(Data!$A$59:$G$59,1,MATCH($B$5,Data!$C$55:$G$55,0)+2) -> 0 | C31: =IF(VLOOKUP($B$5,Data!$A$2:$K$6,3,FALSE())=0,0,B31/VLOOKUP($B$5,Data!$A$2:$K$6,3,FALSE())) -> 0 | D31: Voluntary | G31: Director of QA | H31: =INDEX(Data!$A$38:$F$38,1,MATCH($B$5,Data!$B$20:$F$20,0)+1) -> 0 | I31: =IF(VLOOKUP($B$5,Data!$A$2:$K$6,3,FALSE())=0,0,H31/VLOOKUP($B$5,Data!$A$2:$K$6,3,FALSE())) -> 0 | J31: =IF(VLOOKUP($B$5,Data!$A$2:$K$6,2,FALSE())=0,0,H31/VLOOKUP($B$5,Data!$A$2:$K$6,2,FALSE())) -> 0
A32: Retirement | B32: =INDEX(Data!$A$60:$G$60,1,MATCH($B$5,Data!$C$55:$G$55,0)+2) -> 0 | C32: =IF(VLOOKUP($B$5,Data!$A$2:$K$6,3,FALSE())=0,0,B32/VLOOKUP($B$5,Data!$A$2:$K$6,3,FALSE())) -> 0 | D32: Voluntary | G32: DIRECT CARE
A33: Termination | B33: =INDEX(Data!$A$61:$G$61,1,MATCH($B$5,Data!$C$55:$G$55,0)+2) -> 4 | C33: =IF(VLOOKUP($B$5,Data!$A$2:$K$6,3,FALSE())=0,0,B33/VLOOKUP($B$5,Data!$A$2:$K$6,3,FALSE())) -> 0.11428571 | D33: Involuntary | G33: DSP | H33: =INDEX(Data!$A$39:$F$39,1,MATCH($B$5,Data!$B$20:$F$20,0)+1) -> 25 | I33: =IF(VLOOKUP($B$5,Data!$A$2:$K$6,3,FALSE())=0,0,H33/VLOOKUP($B$5,Data!$A$2:$K$6,3,FALSE())) -> 0.71428571 | J33: =IF(VLOOKUP($B$5,Data!$A$2:$K$6,2,FALSE())=0,0,H33/VLOOKUP($B$5,Data!$A$2:$K$6,2,FALSE())) -> 0.068306011
A34: Layoff | B34: =INDEX(Data!$A$62:$G$62,1,MATCH($B$5,Data!$C$55:$G$55,0)+2) -> 0 | C34: =IF(VLOOKUP($B$5,Data!$A$2:$K$6,3,FALSE())=0,0,B34/VLOOKUP($B$5,Data!$A$2:$K$6,3,FALSE())) -> 0 | D34: Involuntary | G34: HM | H34: =INDEX(Data!$A$40:$F$40,1,MATCH($B$5,Data!$B$20:$F$20,0)+1) -> 3 | I34: =IF(VLOOKUP($B$5,Data!$A$2:$K$6,3,FALSE())=0,0,H34/VLOOKUP($B$5,Data!$A$2:$K$6,3,FALSE())) -> 0.085714286 | J34: =IF(VLOOKUP($B$5,Data!$A$2:$K$6,2,FALSE())=0,0,H34/VLOOKUP($B$5,Data!$A$2:$K$6,2,FALSE())) -> 0.0081967213
A35: Job Abandonment | B35: =INDEX(Data!$A$63:$G$63,1,MATCH($B$5,Data!$C$55:$G$55,0)+2) -> 1 | C35: =IF(VLOOKUP($B$5,Data!$A$2:$K$6,3,FALSE())=0,0,B35/VLOOKUP($B$5,Data!$A$2:$K$6,3,FALSE())) -> 0.028571429 | D35: Other | G35: RM | H35: =INDEX(Data!$A$41:$F$41,1,MATCH($B$5,Data!$B$20:$F$20,0)+1) -> 0 | I35: =IF(VLOOKUP($B$5,Data!$A$2:$K$6,3,FALSE())=0,0,H35/VLOOKUP($B$5,Data!$A$2:$K$6,3,FALSE())) -> 0 | J35: =IF(VLOOKUP($B$5,Data!$A$2:$K$6,2,FALSE())=0,0,H35/VLOOKUP($B$5,Data!$A$2:$K$6,2,FALSE())) -> 0
A36: End of Contract | B36: =INDEX(Data!$A$64:$G$64,1,MATCH($B$5,Data!$C$55:$G$55,0)+2) -> 0 | C36: =IF(VLOOKUP($B$5,Data!$A$2:$K$6,3,FALSE())=0,0,B36/VLOOKUP($B$5,Data!$A$2:$K$6,3,FALSE())) -> 0 | D36: Other | G36: CLINICAL / PROGRAM
A37: Other | B37: =INDEX(Data!$A$65:$G$65,1,MATCH($B$5,Data!$C$55:$G$55,0)+2) -> 2 | C37: =IF(VLOOKUP($B$5,Data!$A$2:$K$6,3,FALSE())=0,0,B37/VLOOKUP($B$5,Data!$A$2:$K$6,3,FALSE())) -> 0.057142857 | D37: Other | G37: CM | H37: =INDEX(Data!$A$42:$F$42,1,MATCH($B$5,Data!$B$20:$F$20,0)+1) -> 1 | I37: =IF(VLOOKUP($B$5,Data!$A$2:$K$6,3,FALSE())=0,0,H37/VLOOKUP($B$5,Data!$A$2:$K$6,3,FALSE())) -> 0.028571429 | J37: =IF(VLOOKUP($B$5,Data!$A$2:$K$6,2,FALSE())=0,0,H37/VLOOKUP($B$5,Data!$A$2:$K$6,2,FALSE())) -> 0.0027322404
A38: Performance Issues | B38: =INDEX(Data!$A$66:$G$66,1,MATCH($B$5,Data!$C$55:$G$55,0)+2) -> 1 | C38: =IF(VLOOKUP($B$5,Data!$A$2:$K$6,3,FALSE())=0,0,B38/VLOOKUP($B$5,Data!$A$2:$K$6,3,FALSE())) -> 0.028571429 | D38: Other | G38: EI | H38: =INDEX(Data!$A$43:$F$43,1,MATCH($B$5,Data!$B$20:$F$20,0)+1) -> 0 | I38: =IF(VLOOKUP($B$5,Data!$A$2:$K$6,3,FALSE())=0,0,H38/VLOOKUP($B$5,Data!$A$2:$K$6,3,FALSE())) -> 0 | J38: =IF(VLOOKUP($B$5,Data!$A$2:$K$6,2,FALSE())=0,0,H38/VLOOKUP($B$5,Data!$A$2:$K$6,2,FALSE())) -> 0
A39: Attendance Issues | B39: =INDEX(Data!$A$67:$G$67,1,MATCH($B$5,Data!$C$55:$G$55,0)+2) -> 1 | C39: =IF(VLOOKUP($B$5,Data!$A$2:$K$6,3,FALSE())=0,0,B39/VLOOKUP($B$5,Data!$A$2:$K$6,3,FALSE())) -> 0.028571429 | D39: Other | G39: Family Support | H39: =INDEX(Data!$A$44:$F$44,1,MATCH($B$5,Data!$B$20:$F$20,0)+1) -> 0 | I39: =IF(VLOOKUP($B$5,Data!$A$2:$K$6,3,FALSE())=0,0,H39/VLOOKUP($B$5,Data!$A$2:$K$6,3,FALSE())) -> 0 | J39: =IF(VLOOKUP($B$5,Data!$A$2:$K$6,2,FALSE())=0,0,H39/VLOOKUP($B$5,Data!$A$2:$K$6,2,FALSE())) -> 0
G40: EDUCATION
B41: Voluntary | C41: =VLOOKUP($B$5,Data!$A$2:$K$6,6,FALSE()) -> 21 | D41: =IF(VLOOKUP($B$5,Data!$A$2:$K$6,3,FALSE())=0,0,C41/VLOOKUP($B$5,Data!$A$2:$K$6,3,FALSE())) -> 0.6 | G41: Teacher | H41: =INDEX(Data!$A$45:$F$45,1,MATCH($B$5,Data!$B$20:$F$20,0)+1) -> 0 | I41: =IF(VLOOKUP($B$5,Data!$A$2:$K$6,3,FALSE())=0,0,H41/VLOOKUP($B$5,Data!$A$2:$K$6,3,FALSE())) -> 0 | J41: =IF(VLOOKUP($B$5,Data!$A$2:$K$6,2,FALSE())=0,0,H41/VLOOKUP($B$5,Data!$A$2:$K$6,2,FALSE())) -> 0
B42: Involuntary | C42: =VLOOKUP($B$5,Data!$A$2:$K$6,7,FALSE()) -> 4 | D42: =IF(VLOOKUP($B$5,Data!$A$2:$K$6,3,FALSE())=0,0,C42/VLOOKUP($B$5,Data!$A$2:$K$6,3,FALSE())) -> 0.11428571 | G42: Assistant Teacher | H42: =INDEX(Data!$A$46:$F$46,1,MATCH($B$5,Data!$B$20:$F$20,0)+1) -> 0 | I42: =IF(VLOOKUP($B$5,Data!$A$2:$K$6,3,FALSE())=0,0,H42/VLOOKUP($B$5,Data!$A$2:$K$6,3,FALSE())) -> 0 | J42: =IF(VLOOKUP($B$5,Data!$A$2:$K$6,2,FALSE())=0,0,H42/VLOOKUP($B$5,Data!$A$2:$K$6,2,FALSE())) -> 0
B43: Other | C43: =VLOOKUP($B$5,Data!$A$2:$K$6,8,FALSE()) -> 10 | D43: =IF(VLOOKUP($B$5,Data!$A$2:$K$6,3,FALSE())=0,0,C43/VLOOKUP($B$5,Data!$A$2:$K$6,3,FALSE())) -> 0.28571429 | G43: SUPPORT
G44: Sub/Floater | H44: =INDEX(Data!$A$47:$F$47,1,MATCH($B$5,Data!$B$20:$F$20,0)+1) -> 1 | I44: =IF(VLOOKUP($B$5,Data!$A$2:$K$6,3,FALSE())=0,0,H44/VLOOKUP($B$5,Data!$A$2:$K$6,3,FALSE())) -> 0.028571429 | J44: =IF(VLOOKUP($B$5,Data!$A$2:$K$6,2,FALSE())=0,0,H44/VLOOKUP($B$5,Data!$A$2:$K$6,2,FALSE())) -> 0.0027322404
...

Sheet Multi-Year Analytics
A2: MULTI-YEAR TURNOVER ANALYTICS & TRENDS
A3: Comparative Analysis Across Calendar Years | January 1 — December 31
A5: YEAR-OVER-YEAR TURNOVER COMPARISON
A7: Metric | B7: FY 2023 | C7: FY 2024 | D7: FY 2025 | E7: FY 2026 | F7: FY 2027 | G7: Avg | H7: Trend
A8: Turnover Rate % | B8: =Data!D2 -> 0.18289086 | C8: =Data!D3 -> 0.4660767 | D8: =Data!D4 -> 0.39884393 | E8: =Data!D5 -> 0.095628415 | F8: =Data!D6 -> 0 | G8: =AVERAGE(B8:F8) -> 0.22868798 | H8: =IF(F8>E8,"↑",IF(F8<E8,"↓","→")) -> ↓
A9: Total Separations | B9: =Data!C2 -> 62 | C9: =Data!C3 -> 158 | D9: =Data!C4 -> 138 | E9: =Data!C5 -> 35 | F9: =Data!C6 -> 0 | G9: =AVERAGE(B9:F9) -> 78.6 | H9: =IF(F9>E9,"↑",IF(F9<E9,"↓","→")) -> ↓
A10: Voluntary % | B10: =Data!I2 -> 0.58064516 | C10: =Data!I3 -> 0.55063291 | D10: =Data!I4 -> 0.71014493 | E10: =Data!I5 -> 0.6 | F10: =Data!I6 -> 0 | G10: =AVERAGE(B10:F10) -> 0.4882846 | H10: =IF(F10>E10,"↑",IF(F10<E10,"↓","→")) -> ↓
A11: Avg Monthly Separations | B11: =Data!E2 -> 10.333333 | C11: =Data!E3 -> 13.166667 | D11: =Data!E4 -> 11.5 | E11: =Data!E5 -> 8.75 | F11: =Data!E6 -> 0 | G11: =AVERAGE(B11:F11) -> 8.75 | H11: =IF(F11>E11,"↑",IF(F11<E11,"↓","→")) -> ↓
A13: JOB/DEPARTMENT TURNOVER ACROSS YEARS
A15: Job | B15: FY 2023 | C15: FY 2024 | D15: FY 2025 | E15: FY 2026 | F15: FY 2027 | G15: Total
A16: LEADERSHIP
A17: President | B17: =Data!B21 -> 0 | C17: =Data!C21 -> 0 | D17: =Data!D21 -> 0 | E17: =Data!E21 -> 0 | F17: =Data!F21 -> 0 | G17: =SUM(B17:F17) -> 0
A18: VP of Operations | B18: =Data!B22 -> 0 | C18: =Data!C22 -> 0 | D18: =Data!D22 -> 0 | E18: =Data!E22 -> 0 | F18: =Data!F22 -> 0 | G18: =SUM(B18:F18) -> 0
A19: VP of Children Services | B19: =Data!B23 -> 0 | C19: =Data!C23 -> 0 | D19: =Data!D23 -> 0 | E19: =Data!E23 -> 0 | F19: =Data!F23 -> 0 | G19: =SUM(B19:F19) -> 0
A20: VP of Professional Services | B20: =Data!B24 -> 0 | C20: =Data!C24 -> 0 | D20: =Data!D24 -> 0 | E20: =Data!E24 -> 0 | F20: =Data!F24 -> 0 | G20: =SUM(B20:F20) -> 0
A21: VP of Behavioral Health | B21: =Data!B25 -> 0 | C21: =Data!C25 -> 0 | D21: =Data!D25 -> 0 | E21: =Data!E25 -> 0 | F21: =Data!F25 -> 0 | G21: =SUM(B21:F21) -> 0
A22: VP of Human Resources | B22: =Data!B26 -> 0 | C22: =Data!C26 -> 0 | D22: =Data!D26 -> 0 | E22: =Data!E26 -> 0 | F22: =Data!F26 -> 0 | G22: =SUM(B22:F22) -> 0
A23: VP of Employment Services | B23: =Data!B27 -> 0 | C23: =Data!C27 -> 0 | D23: =Data!D27 -> 0 | E23: =Data!E27 -> 0 | F23: =Data!F27 -> 0 | G23: =SUM(B23:F23) -> 0
A24: VP of Family Support | B24: =Data!B28 -> 0 | C24: =Data!C28 -> 0 | D24: =Data!D28 -> 0 | E24: =Data!E28 -> 0 | F24: =Data!F28 -> 0 | G24: =SUM(B24:F24) -> 0
A25: VP of Finance | B25: =Data!B29 -> 0 | C25: =Data!C29 -> 0 | D25: =Data!D29 -> 0 | E25: =Data!E29 -> 1 | F25: =Data!F29 -> 0 | G25: =SUM(B25:F25) -> 1
A26: Director of Operations | B26: =Data!B30 -> 0 | C26: =Data!C30 -> 0 | D26: =Data!D30 -> 0 | E26: =Data!E30 -> 0 | F26: =Data!F30 -> 0 | G26: =SUM(B26:F26) -> 0
A27: Director of Children Services | B27: =Data!B31 -> 0 | C27: =Data!C31 -> 1 | D27: =Data!D31 -> 1 | E27: =Data!E31 -> 0 | F27: =Data!F31 -> 0 | G27: =SUM(B27:F27) -> 2
A28: Director of Professional Services | B28: =Data!B32 -> 0 | C28: =Data!C32 -> 0 | D28: =Data!D32 -> 1 | E28: =Data!E32 -> 0 | F28: =Data!F32 -> 0 | G28: =SUM(B28:F28) -> 1
... A34: Director of QA | B34: =Data!B38 -> 0 | C34: =Data!C38 -> 0 | D34: =Data!D38 -> 0 | E34: =Data!E38 -> 0 | F34: =Data!F38 -> 0 | G34: =SUM(B34:F34) -> 0
A35: DIRECT CARE
A36: DSP | B36: =Data!B39 -> 45 | C36: =Data!C39 -> 120 | D36: =Data!D39 -> 75 | E36: =Data!E39 -> 25 | F36: =Data!F39 -> 0 | G36: =SUM(B36:F36) -> 265
A37: HM | B37: =Data!B40 -> 0 | C37: =Data!C40 -> 8 | D37: =Data!D40 -> 5 | E37: =Data!E40 -> 3 | F37: =Data!F40 -> 0 | G37: =SUM(B37:F37) -> 16
A38: RM | B38: =Data!B41 -> 0 | C38: =Data!C41 -> 3 | D38: =Data!D41 -> 0 | E38: =Data!E41 -> 0 | F38: =Data!F41 -> 0 | G38: =SUM(B38:F38) -> 3
A39: CLINICAL / PROGRAM
A40: CM | B40: =Data!B42 -> 0 | C40: =Data!C42 -> 1 | D40: =Data!D42 -> 6 | E40: =Data!E42 -> 1 | F40: =Data!F42 -> 0 | G40: =SUM(B40:F40) -> 8
A41: EI | B41: =Data!B43 -> 4 | C41: =Data!C43 -> 5 | D41: =Data!D43 -> 6 | E41: =Data!E43 -> 0 | F41: =Data!F43 -> 0 | G41: =SUM(B41:F41) -> 15
A42: Family Support | B42: =Data!B44 -> 0 | C42: =Data!C44 -> 1 | D42: =Data!D44 -> 2 | E42: =Data!E44 -> 0 | F42: =Data!F44 -> 0 | G42: =SUM(B42:F42) -> 3
A43: EDUCATION
A44: Teacher | B44: =Data!B45 -> 0 | C44: =Data!C45 -> 3 | D44: =Data!D45 -> 4 | E44: =Data!E45 -> 0 | F44: =Data!F45 -> 0 | G44: =SUM(B44:F44) -> 7
A45: Assistant Teacher | B45: =Data!B46 -> 0 | C45: =Data!C46 -> 3 | D45: =Data!D46 -> 4 | E45: =Data!E46 -> 0 | F45: =Data!F46 -> 0 | G45: =SUM(B45:F45) -> 7
A46: SUPPORT
A47: Sub/Floater | B47: =Data!B47 -> 5 | C47: =Data!C47 -> 1 | D47: =Data!D47 -> 14 | E47: =Data!E47 -> 1 | F47: =Data!F47 -> 0 | G47: =SUM(B47:F47) -> 21
A48: Job Coach/WI | B48: =Data!B48 -> 0 | C48: =Data!C48 -> 5 | D48: =Data!D48 -> 2 | E48: =Data!E48 -> 0 | F48: =Data!F48 -> 0 | G48: =SUM(B48:F48) -> 7
A49: ADMINISTRATIVE
A50: Finance | B50: =Data!B49 -> 0 | C50: =Data!C49 -> 0 | D50: =Data!D49 -> 3 | E50: =Data!E49 -> 0 | F50: =Data!F49 -> 0 | G50: =SUM(B50:F50) -> 3
...

Sheet FY 2027 (Jan27-Dec27)
A2: EMPLOYEE SEPARATION SUMMARY — FY 2027
A3: January 2027 — December 2027 | Emory Valley Center
A5: Active Employees: | B5: 364 | D5: YTD Separations: | E5: =B39+B73+B107+B141+B175+B209+B243+B277+B311+B345+B379+B413 -> 0 | G5: TOR %: | H5: =IF(B5=0,0,E5/B5) -> 0
A7: JANUARY 2027
A8: Name | B8: Date of Separation | C8: DOH | D8: Length of Service | E8: Eligible for Rehire | F8: Status | G8: Location | H8: Reason for Leaving | I8: Supervisor | J8: Exit Interview Date | K8: Job | L8: Comments | M8: Department
D9: =IF(OR(B9="",C9=""),"",IF(DATEDIF(C9,B9,"y")>=1,DATEDIF(C9,B9,"y")&IF(DATEDIF(C9,B9,"y")=1," year "," years ")&DATEDIF(C9,B9,"ym")&IF(DATEDIF(C9,B9,"ym")=1," month"," months"),IF(DATEDIF(C9,B9,"m")>=1,DATEDIF(C9,B9,"m")&IF(DATEDIF(C9,B9,"m")=1," month"," months"),DATEDIF(C9,B9,"d")&IF(DATEDIF(C9,B9,"d")=1," day"," days")))) | M9: =IFERROR(VLOOKUP(G9,Reference!$I$2:$J$175,2,FALSE()),"Operations") -> Operations
D10: =IF(OR(B10="",C10=""),"",IF(DATEDIF(C10,B10,"y")>=1,DATEDIF(C10,B10,"y")&IF(DATEDIF(C10,B10,"y")=1," year "," years ")&DATEDIF(C10,B10,"ym")&IF(DATEDIF(C10,B10,"ym")=1," month"," months"),IF(DATEDIF(C10,B10,"m")>=1,DATEDIF(C10,B10,"m")&IF(DATEDIF(C10,B10,"m")=1," month"," months"),DATEDIF(C10,B10,"d")&IF(DATEDIF(C10,B10,"d")=1," day"," days")))) | M10: =IFERROR(VLOOKUP(G10,Reference!$I$2:$J$175,2,FALSE()),"Operations") -> Operations
D11: =IF(OR(B11="",C11=""),"",IF(DATEDIF(C11,B11,"y")>=1,DATEDIF(C11,B11,"y")&IF(DATEDIF(C11,B11,"y")=1," year "," years ")&DATEDIF(C11,B11,"ym")&IF(DATEDIF(C11,B11,"ym")=1," month"," months"),IF(DATEDIF(C11,B11,"m")>=1,DATEDIF(C11,B11,"m")&IF(DATEDIF(C11,B11,"m")=1," month"," months"),DATEDIF(C11,B11,"d")&IF(DATEDIF(C11,B11,"d")=1," day"," days")))) | M11: =IFERROR(VLOOKUP(G11,Reference!$I$2:$J$175,2,FALSE()),"Operations") -> Operations
D12: =IF(OR(B12="",C12=""),"",IF(DATEDIF(C12,B12,"y")>=1,DATEDIF(C12,B12,"y")&IF(DATEDIF(C12,B12,"y")=1," year "," years ")&DATEDIF(C12,B12,"ym")&IF(DATEDIF(C12,B12,"ym")=1," month"," months"),IF(DATEDIF(C12,B12,"m")>=1,DATEDIF(C12,B12,"m")&IF(DATEDIF(C12,B12,"m")=1," month"," months"),DATEDIF(C12,B12,"d")&IF(DATEDIF(C12,B12,"d")=1," day"," days")))) | M12: =IFERROR(VLOOKUP(G12,Reference!$I$2:$J$175,2,FALSE()),"Operations") -> Operations
D13: =IF(OR(B13="",C13=""),"",IF(DATEDIF(C13,B13,"y")>=1,DATEDIF(C13,B13,"y")&IF(DATEDIF(C13,B13,"y")=1," year "," years ")&DATEDIF(C13,B13,"ym")&IF(DATEDIF(C13,B13,"ym")=1," month"," months"),IF(DATEDIF(C13,B13,"m")>=1,DATEDIF(C13,B13,"m")&IF(DATEDIF(C13,B13,"m")=1," month"," months"),DATEDIF(C13,B13,"d")&IF(DATEDIF(C13,B13,"d")=1," day"," days")))) | M13: =IFERROR(VLOOKUP(G13,Reference!$I$2:$J$175,2,FALSE()),"Operations") -> Operations
D14: =IF(OR(B14="",C14=""),"",IF(DATEDIF(C14,B14,"y")>=1,DATEDIF(C14,B14,"y")&IF(DATEDIF(C14,B14,"y")=1," year "," years ")&DATEDIF(C14,B14,"ym")&IF(DATEDIF(C14,B14,"ym")=1," month"," months"),IF(DATEDIF(C14,B14,"m")>=1,DATEDIF(C14,B14,"m")&IF(DATEDIF(C14,B14,"m")=1," month"," months"),DATEDIF(C14,B14,"d")&IF(DATEDIF(C14,B14,"d")=1," day"," days")))) | M14: =IFERROR(VLOOKUP(G14,Reference!$I$2:$J$175,2,FALSE()),"Operations") -> Operations
D15: =IF(OR(B15="",C15=""),"",IF(DATEDIF(C15,B15,"y")>=1,DATEDIF(C15,B15,"y")&IF(DATEDIF(C15,B15,"y")=1," year "," years ")&DATEDIF(C15,B15,"ym")&IF(DATEDIF(C15,B15,"ym")=1," month"," months"),IF(DATEDIF(C15,B15,"m")>=1,DATEDIF(C15,B15,"m")&IF(DATEDIF(C15,B15,"m")=1," month"," months"),DATEDIF(C15,B15,"d")&IF(DATEDIF(C15,B15,"d")=1," day"," days")))) | M15: =IFERROR(VLOOKUP(G15,Reference!$I$2:$J$175,2,FALSE()),"Operations") -> Operations
D16: =IF(OR(B16="",C16=""),"",IF(DATEDIF(C16,B16,"y")>=1,DATEDIF(C16,B16,"y")&IF(DATEDIF(C16,B16,"y")=1," year "," years ")&DATEDIF(C16,B16,"ym")&IF(DATEDIF(C16,B16,"ym")=1," month"," months"),IF(DATEDIF(C16,B16,"m")>=1,DATEDIF(C16,B16,"m")&IF(DATEDIF(C16,B16,"m")=1," month"," months"),DATEDIF(C16,B16,"d")&IF(DATEDIF(C16,B16,"d")=1," day"," days")))) | M16: =IFERROR(VLOOKUP(G16,Reference!$I$2:$J$175,2,FALSE()),"Operations") -> Operations
D17: =IF(OR(B17="",C17=""),"",IF(DATEDIF(C17,B17,"y")>=1,DATEDIF(C17,B17,"y")&IF(DATEDIF(C17,B17,"y")=1," year "," years ")&DATEDIF(C17,B17,"ym")&IF(DATEDIF(C17,B17,"ym")=1," month"," months"),IF(DATEDIF(C17,B17,"m")>=1,DATEDIF(C17,B17,"m")&IF(DATEDIF(C17,B17,"m")=1," month"," months"),DATEDIF(C17,B17,"d")&IF(DATEDIF(C17,B17,"d")=1," day"," days")))) | M17: =IFERROR(VLOOKUP(G17,Reference!$I$2:$J$175,2,FALSE()),"Operations") -> Operations
D18: =IF(OR(B18="",C18=""),"",IF(DATEDIF(C18,B18,"y")>=1,DATEDIF(C18,B18,"y")&IF(DATEDIF(C18,B18,"y")=1," year "," years ")&DATEDIF(C18,B18,"ym")&IF(DATEDIF(C18,B18,"ym")=1," month"," months"),IF(DATEDIF(C18,B18,"m")>=1,DATEDIF(C18,B18,"m")&IF(DATEDIF(C18,B18,"m")=1," month"," months"),DATEDIF(C18,B18,"d")&IF(DATEDIF(C18,B18,"d")=1," day"," days")))) | M18: =IFERROR(VLOOKUP(G18,Reference!$I$2:$J$175,2,FALSE()),"Operations") -> Operations
D19: =IF(OR(B19="",C19=""),"",IF(DATEDIF(C19,B19,"y")>=1,DATEDIF(C19,B19,"y")&IF(DATEDIF(C19,B19,"y")=1," year "," years ")&DATEDIF(C19,B19,"ym")&IF(DATEDIF(C19,B19,"ym")=1," month"," months"),IF(DATEDIF(C19,B19,"m")>=1,DATEDIF(C19,B19,"m")&IF(DATEDIF(C19,B19,"m")=1," month"," months"),DATEDIF(C19,B19,"d")&IF(DATEDIF(C19,B19,"d")=1," day"," days")))) | M19: =IFERROR(VLOOKUP(G19,Reference!$I$2:$J$175,2,FALSE()),"Operations") -> Operations
D20: =IF(OR(B20="",C20=""),"",IF(DATEDIF(C20,B20,"y")>=1,DATEDIF(C20,B20,"y")&IF(DATEDIF(C20,B20,"y")=1," year "," years ")&DATEDIF(C20,B20,"ym")&IF(DATEDIF(C20,B20,"ym")=1," month"," months"),IF(DATEDIF(C20,B20,"m")>=1,DATEDIF(C20,B20,"m")&IF(DATEDIF(C20,B20,"m")=1," month"," months"),DATEDIF(C20,B20,"d")&IF(DATEDIF(C20,B20,"d")=1," day"," days")))) | M20: =IFERROR(VLOOKUP(G20,Reference!$I$2:$J$175,2,FALSE()),"Operations") -> Operations
... D38: =IF(OR(B38="",C38=""),"",IF(DATEDIF(C38,B38,"y")>=1,DATEDIF(C38,B38,"y")&IF(DATEDIF(C38,B38,"y")=1," year "," years ")&DATEDIF(C38,B38,"ym")&IF(DATEDIF(C38,B38,"ym")=1," month"," months"),IF(DATEDIF(C38,B38,"m")>=1,DATEDIF(C38,B38,"m")&IF(DATEDIF(C38,B38,"m")=1," month"," months"),DATEDIF(C38,B38,"d")&IF(DATEDIF(C38,B38,"d")=1," day"," days")))) | M38: =IFERROR(VLOOKUP(G38,Reference!$I$2:$J$175,2,FALSE()),"Operations") -> Operations
A39: SUBTOTAL: | B39: =COUNTA(A9:A38) -> 0
A41: FEBRUARY 2027
A42: Name | B42: Date of Separation | C42: DOH | D42: Length of Service | E42: Eligible for Rehire | F42: Status | G42: Location | H42: Reason for Leaving | I42: Supervisor | J42: Exit Interview Date | K42: Job | L42: Comments | M42: Department
D43: =IF(OR(B43="",C43=""),"",IF(DATEDIF(C43,B43,"y")>=1,DATEDIF(C43,B43,"y")&IF(DATEDIF(C43,B43,"y")=1," year "," years ")&DATEDIF(C43,B43,"ym")&IF(DATEDIF(C43,B43,"ym")=1," month"," months"),IF(DATEDIF(C43,B43,"m")>=1,DATEDIF(C43,B43,"m")&IF(DATEDIF(C43,B43,"m")=1," month"," months"),DATEDIF(C43,B43,"d")&IF(DATEDIF(C43,B43,"d")=1," day"," days")))) | M43: =IFERROR(VLOOKUP(G43,Reference!$I$2:$J$175,2,FALSE()),"Operations") -> Operations
D44: =IF(OR(B44="",C44=""),"",IF(DATEDIF(C44,B44,"y")>=1,DATEDIF(C44,B44,"y")&IF(DATEDIF(C44,B44,"y")=1," year "," years ")&DATEDIF(C44,B44,"ym")&IF(DATEDIF(C44,B44,"ym")=1," month"," months"),IF(DATEDIF(C44,B44,"m")>=1,DATEDIF(C44,B44,"m")&IF(DATEDIF(C44,B44,"m")=1," month"," months"),DATEDIF(C44,B44,"d")&IF(DATEDIF(C44,B44,"d")=1," day"," days")))) | M44: =IFERROR(VLOOKUP(G44,Reference!$I$2:$J$175,2,FALSE()),"Operations") -> Operations
D45: =IF(OR(B45="",C45=""),"",IF(DATEDIF(C45,B45,"y")>=1,DATEDIF(C45,B45,"y")&IF(DATEDIF(C45,B45,"y")=1," year "," years ")&DATEDIF(C45,B45,"ym")&IF(DATEDIF(C45,B45,"ym")=1," month"," months"),IF(DATEDIF(C45,B45,"m")>=1,DATEDIF(C45,B45,"m")&IF(DATEDIF(C45,B45,"m")=1," month"," months"),DATEDIF(C45,B45,"d")&IF(DATEDIF(C45,B45,"d")=1," day"," days")))) | M45: =IFERROR(VLOOKUP(G45,Reference!$I$2:$J$175,2,FALSE()),"Operations") -> Operations
D46: =IF(OR(B46="",C46=""),"",IF(DATEDIF(C46,B46,"y")>=1,DATEDIF(C46,B46,"y")&IF(DATEDIF(C46,B46,"y")=1," year "," years ")&DATEDIF(C46,B46,"ym")&IF(DATEDIF(C46,B46,"ym")=1," month"," months"),IF(DATEDIF(C46,B46,"m")>=1,DATEDIF(C46,B46,"m")&IF(DATEDIF(C46,B46,"m")=1," month"," months"),DATEDIF(C46,B46,"d")&IF(DATEDIF(C46,B46,"d")=1," day"," days")))) | M46: =IFERROR(VLOOKUP(G46,Reference!$I$2:$J$175,2,FALSE()),"Operations") -> Operations
D47: =IF(OR(B47="",C47=""),"",IF(DATEDIF(C47,B47,"y")>=1,DATEDIF(C47,B47,"y")&IF(DATEDIF(C47,B47,"y")=1," year "," years ")&DATEDIF(C47,B47,"ym")&IF(DATEDIF(C47,B47,"ym")=1," month"," months"),IF(DATEDIF(C47,B47,"m")>=1,DATEDIF(C47,B47,"m")&IF(DATEDIF(C47,B47,"m")=1," month"," months"),DATEDIF(C47,B47,"d")&IF(DATEDIF(C47,B47,"d")=1," day"," days")))) | M47: =IFERROR(VLOOKUP(G47,Reference!$I$2:$J$175,2,FALSE()),"Operations") -> Operations
D48: =IF(OR(B48="",C48=""),"",IF(DATEDIF(C48,B48,"y")>=1,DATEDIF(C48,B48,"y")&IF(DATEDIF(C48,B48,"y")=1," year "," years ")&DATEDIF(C48,B48,"ym")&IF(DATEDIF(C48,B48,"ym")=1," month"," months"),IF(DATEDIF(C48,B48,"m")>=1,DATEDIF(C48,B48,"m")&IF(DATEDIF(C48,B48,"m")=1," month"," months"),DATEDIF(C48,B48,"d")&IF(DATEDIF(C48,B48,"d")=1," day"," days")))) | M48: =IFERROR(VLOOKUP(G48,Reference!$I$2:$J$175,2,FALSE()),"Operations") -> Operations
D49: =IF(OR(B49="",C49=""),"",IF(DATEDIF(C49,B49,"y")>=1,DATEDIF(C49,B49,"y")&IF(DATEDIF(C49,B49,"y")=1," year "," years ")&DATEDIF(C49,B49,"ym")&IF(DATEDIF(C49,B49,"ym")=1," month"," months"),IF(DATEDIF(C49,B49,"m")>=1,DATEDIF(C49,B49,"m")&IF(DATEDIF(C49,B49,"m")=1," month"," months"),DATEDIF(C49,B49,"d")&IF(DATEDIF(C49,B49,"d")=1," day"," days")))) | M49: =IFERROR(VLOOKUP(G49,Reference!$I$2:$J$175,2,FALSE()),"Operations") -> Operations
D50: =IF(OR(B50="",C50=""),"",IF(DATEDIF(C50,B50,"y")>=1,DATEDIF(C50,B50,"y")&IF(DATEDIF(C50,B50,"y")=1," year "," years ")&DATEDIF(C50,B50,"ym")&IF(DATEDIF(C50,B50,"ym")=1," month"," months"),IF(DATEDIF(C50,B50,"m")>=1,DATEDIF(C50,B50,"m")&IF(DATEDIF(C50,B50,"m")=1," month"," months"),DATEDIF(C50,B50,"d")&IF(DATEDIF(C50,B50,"d")=1," day"," days")))) | M50: =IFERROR(VLOOKUP(G50,Reference!$I$2:$J$175,2,FALSE()),"Operations") -> Operations
D51: =IF(OR(B51="",C51=""),"",IF(DATEDIF(C51,B51,"y")>=1,DATEDIF(C51,B51,"y")&IF(DATEDIF(C51,B51,"y")=1," year "," years ")&DATEDIF(C51,B51,"ym")&IF(DATEDIF(C51,B51,"ym")=1," month"," months"),IF(DATEDIF(C51,B51,"m")>=1,DATEDIF(C51,B51,"m")&IF(DATEDIF(C51,B51,"m")=1," month"," months"),DATEDIF(C51,B51,"d")&IF(DATEDIF(C51,B51,"d")=1," day"," days")))) | M51: =IFERROR(VLOOKUP(G51,Reference!$I$2:$J$175,2,FALSE()),"Operations") -> Operations
D52: =IF(OR(B52="",C52=""),"",IF(DATEDIF(C52,B52,"y")>=1,DATEDIF(C52,B52,"y")&IF(DATEDIF(C52,B52,"y")=1," year "," years ")&DATEDIF(C52,B52,"ym")&IF(DATEDIF(C52,B52,"ym")=1," month"," months"),IF(DATEDIF(C52,B52,"m")>=1,DATEDIF(C52,B52,"m")&IF(DATEDIF(C52,B52,"m")=1," month"," months"),DATEDIF(C52,B52,"d")&IF(DATEDIF(C52,B52,"d")=1," day"," days")))) | M52: =IFERROR(VLOOKUP(G52,Reference!$I$2:$J$175,2,FALSE()),"Operations") -> Operations
D53: =IF(OR(B53="",C53=""),"",IF(DATEDIF(C53,B53,"y")>=1,DATEDIF(C53,B53,"y")&IF(DATEDIF(C53,B53,"y")=1," year "," years ")&DATEDIF(C53,B53,"ym")&IF(DATEDIF(C53,B53,"ym")=1," month"," months"),IF(DATEDIF(C53,B53,"m")>=1,DATEDIF(C53,B53,"m")&IF(DATEDIF(C53,B53,"m")=1," month"," months"),DATEDIF(C53,B53,"d")&IF(DATEDIF(C53,B53,"d")=1," day"," days")))) | M53: =IFERROR(VLOOKUP(G53,Reference!$I$2:$J$175,2,FALSE()),"Operations") -> Operations
D54: =IF(OR(B54="",C54=""),"",IF(DATEDIF(C54,B54,"y")>=1,DATEDIF(C54,B54,"y")&IF(DATEDIF(C54,B54,"y")=1," year "," years ")&DATEDIF(C54,B54,"ym")&IF(DATEDIF(C54,B54,"ym")=1," month"," months"),IF(DATEDIF(C54,B54,"m")>=1,DATEDIF(C54,B54,"m")&IF(DATEDIF(C54,B54,"m")=1," month"," months"),DATEDIF(C54,B54,"d")&IF(DATEDIF(C54,B54,"d")=1," day"," days")))) | M54: =IFERROR(VLOOKUP(G54,Reference!$I$2:$J$175,2,FALSE()),"Operations") -> Operations
... D72: =IF(OR(B72="",C72=""),"",IF(DATEDIF(C72,B72,"y")>=1,DATEDIF(C72,B72,"y")&IF(DATEDIF(C72,B72,"y")=1," year "," years ")&DATEDIF(C72,B72,"ym")&IF(DATEDIF(C72,B72,"ym")=1," month"," months"),IF(DATEDIF(C72,B72,"m")>=1,DATEDIF(C72,B72,"m")&IF(DATEDIF(C72,B72,"m")=1," month"," months"),DATEDIF(C72,B72,"d")&IF(DATEDIF(C72,B72,"d")=1," day"," days")))) | M72: =IFERROR(VLOOKUP(G72,Reference!$I$2:$J$175,2,FALSE()),"Operations") -> Operations
A73: SUBTOTAL: | B73: =COUNTA(A43:A72) -> 0
A75: MARCH 2027
A76: Name | B76: Date of Separation | C76: DOH | D76: Length of Service | E76: Eligible for Rehire | F76: Status | G76: Location | H76: Reason for Leaving | I76: Supervisor | J76: Exit Interview Date | K76: Job | L76: Comments | M76: Department
D77: =IF(OR(B77="",C77=""),"",IF(DATEDIF(C77,B77,"y")>=1,DATEDIF(C77,B77,"y")&IF(DATEDIF(C77,B77,"y")=1," year "," years ")&DATEDIF(C77,B77,"ym")&IF(DATEDIF(C77,B77,"ym")=1," month"," months"),IF(DATEDIF(C77,B77,"m")>=1,DATEDIF(C77,B77,"m")&IF(DATEDIF(C77,B77,"m")=1," month"," months"),DATEDIF(C77,B77,"d")&IF(DATEDIF(C77,B77,"d")=1," day"," days")))) | M77: =IFERROR(VLOOKUP(G77,Reference!$I$2:$J$175,2,FALSE()),"Operations") -> Operations
D78: =IF(OR(B78="",C78=""),"",IF(DATEDIF(C78,B78,"y")>=1,DATEDIF(C78,B78,"y")&IF(DATEDIF(C78,B78,"y")=1," year "," years ")&DATEDIF(C78,B78,"ym")&IF(DATEDIF(C78,B78,"ym")=1," month"," months"),IF(DATEDIF(C78,B78,"m")>=1,DATEDIF(C78,B78,"m")&IF(DATEDIF(C78,B78,"m")=1," month"," months"),DATEDIF(C78,B78,"d")&IF(DATEDIF(C78,B78,"d")=1," day"," days")))) | M78: =IFERROR(VLOOKUP(G78,Reference!$I$2:$J$175,2,FALSE()),"Operations") -> Operations
D79: =IF(OR(B79="",C79=""),"",IF(DATEDIF(C79,B79,"y")>=1,DATEDIF(C79,B79,"y")&IF(DATEDIF(C79,B79,"y")=1," year "," years ")&DATEDIF(C79,B79,"ym")&IF(DATEDIF(C79,B79,"ym")=1," month"," months"),IF(DATEDIF(C79,B79,"m")>=1,DATEDIF(C79,B79,"m")&IF(DATEDIF(C79,B79,"m")=1," month"," months"),DATEDIF(C79,B79,"d")&IF(DATEDIF(C79,B79,"d")=1," day"," days")))) | M79: =IFERROR(VLOOKUP(G79,Reference!$I$2:$J$175,2,FALSE()),"Operations") -> Operations
...

Sheet FY 2026 (Jan26-Dec26)
A2: EMPLOYEE SEPARATION SUMMARY — FY 2026
A3: January 2026 — December 2026 | Emory Valley Center
A5: Active Employees: | B5: 366 | D5: YTD Separations: | E5: =B18+B33+B51+B85+B119+B153+B187+B221+B255+B289+B323+B357 -> 35 | G5: TOR %: | H5: =IF(B5=0,0,E5/B5) -> 0.095628415
A7: JANUARY 2026
A8: Name | B8: Date of Separation | C8: DOH | D8: Length of Service | E8: Eligible for Rehire | F8: Status | G8: Location | H8: Reason for Leaving | I8: Supervisor | J8: Exit Interview Date | K8: Job | L8: Comments | M8: Department
A9: Jackie Ross | B9: 46035 | C9: 44655 | D9: =IF(OR(B9="",C9=""),"",IF(DATEDIF(C9,B9,"y")>=1,DATEDIF(C9,B9,"y")&IF(DATEDIF(C9,B9,"y")=1," year "," years ")&DATEDIF(C9,B9,"ym")&IF(DATEDIF(C9,B9,"ym")=1," month"," months"),IF(DATEDIF(C9,B9,"m")>=1,DATEDIF(C9,B9,"m")&IF(DATEDIF(C9,B9,"m")=1," month"," months"),DATEDIF(C9,B9,"d")&IF(DATEDIF(C9,B9,"d")=1," day"," days")))) -> 3 years 9 months | E9: No | F9: D | G9: Livingston | H9: Termination | I9: Kasey Foster | J9: N/A | K9: DSP | M9: =IFERROR(VLOOKUP(G9,Reference!$I$2:$J$175,2,FALSE()),"Operations") -> Operations
A10: Elizabeth Hawkins | B10: 46037 | C10: 42660 | D10: =IF(OR(B10="",C10=""),"",IF(DATEDIF(C10,B10,"y")>=1,DATEDIF(C10,B10,"y")&IF(DATEDIF(C10,B10,"y")=1," year "," years ")&DATEDIF(C10,B10,"ym")&IF(DATEDIF(C10,B10,"ym")=1," month"," months"),IF(DATEDIF(C10,B10,"m")>=1,DATEDIF(C10,B10,"m")&IF(DATEDIF(C10,B10,"m")=1," month"," months"),DATEDIF(C10,B10,"d")&IF(DATEDIF(C10,B10,"d")=1," day"," days")))) -> 9 years 2 months | E10: Yes | F10: D | G10: Quality Assurance | H10: Better Opportunity | I10: Kristen Otto | J10: 46037 | K10: QA | M10: =IFERROR(VLOOKUP(G10,Reference!$I$2:$J$175,2,FALSE()),"Operations") -> QA
A11: Michaela Smith | B11: 46038 | C11: 45054 | D11: =IF(OR(B11="",C11=""),"",IF(DATEDIF(C11,B11,"y")>=1,DATEDIF(C11,B11,"y")&IF(DATEDIF(C11,B11,"y")=1," year "," years ")&DATEDIF(C11,B11,"ym")&IF(DATEDIF(C11,B11,"ym")=1," month"," months"),IF(DATEDIF(C11,B11,"m")>=1,DATEDIF(C11,B11,"m")&IF(DATEDIF(C11,B11,"m")=1," month"," months"),DATEDIF(C11,B11,"d")&IF(DATEDIF(C11,B11,"d")=1," day"," days")))) -> 2 years 8 months | E11: Yes | F11: D | G11: Hamiltons | H11: Personal Reasons | I11: Catie Robinson | J11: 46039 | K11: HM | M11: =IFERROR(VLOOKUP(G11,Reference!$I$2:$J$175,2,FALSE()),"Operations") -> Operations
A12: Beverly Hines | B12: 46038 | C12: 44369 | D12: =IF(OR(B12="",C12=""),"",IF(DATEDIF(C12,B12,"y")>=1,DATEDIF(C12,B12,"y")&IF(DATEDIF(C12,B12,"y")=1," year "," years ")&DATEDIF(C12,B12,"ym")&IF(DATEDIF(C12,B12,"ym")=1," month"," months"),IF(DATEDIF(C12,B12,"m")>=1,DATEDIF(C12,B12,"m")&IF(DATEDIF(C12,B12,"m")=1," month"," months"),DATEDIF(C12,B12,"d")&IF(DATEDIF(C12,B12,"d")=1," day"," days")))) -> 4 years 6 months | E12: No | F12: U | G12: Case Management | H12: Other | I12: Amanda Tackett | J12: No Response | K12: CM | M12: =IFERROR(VLOOKUP(G12,Reference!$I$2:$J$175,2,FALSE()),"Operations") -> Professional Services
A13: Michael Hurd | B13: 46044 | C13: 45404 | D13: =IF(OR(B13="",C13=""),"",IF(DATEDIF(C13,B13,"y")>=1,DATEDIF(C13,B13,"y")&IF(DATEDIF(C13,B13,"y")=1," year "," years ")&DATEDIF(C13,B13,"ym")&IF(DATEDIF(C13,B13,"ym")=1," month"," months"),IF(DATEDIF(C13,B13,"m")>=1,DATEDIF(C13,B13,"m")&IF(DATEDIF(C13,B13,"m")=1," month"," months"),DATEDIF(C13,B13,"d")&IF(DATEDIF(C13,B13,"d")=1," day"," days")))) -> 1 year 9 months | E13: No | F13: U | G13: 2292 Turnpike | H13: Other | I13: Sarah Allen | J13: N/A | K13: DSP | M13: =IFERROR(VLOOKUP(G13,Reference!$I$2:$J$175,2,FALSE()),"Operations") -> Operations
A14: Baylee Stewart | B14: 46044 | C14: 45958 | D14: =IF(OR(B14="",C14=""),"",IF(DATEDIF(C14,B14,"y")>=1,DATEDIF(C14,B14,"y")&IF(DATEDIF(C14,B14,"y")=1," year "," years ")&DATEDIF(C14,B14,"ym")&IF(DATEDIF(C14,B14,"ym")=1," month"," months"),IF(DATEDIF(C14,B14,"m")>=1,DATEDIF(C14,B14,"m")&IF(DATEDIF(C14,B14,"m")=1," month"," months"),DATEDIF(C14,B14,"d")&IF(DATEDIF(C14,B14,"d")=1," day"," days")))) -> 2 months | E14: No | F14: U | G14: 200 Latimer | H14: Termination | I14: Kasey Foster | J14: N/A | K14: DSP | M14: =IFERROR(VLOOKUP(G14,Reference!$I$2:$J$175,2,FALSE()),"Operations") -> Operations
A15: Craig Varner | B15: 46051 | C15: 45082 | D15: =IF(OR(B15="",C15=""),"",IF(DATEDIF(C15,B15,"y")>=1,DATEDIF(C15,B15,"y")&IF(DATEDIF(C15,B15,"y")=1," year "," years ")&DATEDIF(C15,B15,"ym")&IF(DATEDIF(C15,B15,"ym")=1," month"," months"),IF(DATEDIF(C15,B15,"m")>=1,DATEDIF(C15,B15,"m")&IF(DATEDIF(C15,B15,"m")=1," month"," months"),DATEDIF(C15,B15,"d")&IF(DATEDIF(C15,B15,"d")=1," day"," days")))) -> 2 years 7 months | E15: No | F15: U | G15: 122 E. Newkirk Lane | H15: Personal Reasons | I15: Kaelyn Sibley | J15: N/A | K15: DSP | M15: =IFERROR(VLOOKUP(G15,Reference!$I$2:$J$175,2,FALSE()),"Operations") -> Operations
A16: Aaron McCarty | B16: 46051 | C16: 46036 | D16: =IF(OR(B16="",C16=""),"",IF(DATEDIF(C16,B16,"y")>=1,DATEDIF(C16,B16,"y")&IF(DATEDIF(C16,B16,"y")=1," year "," years ")&DATEDIF(C16,B16,"ym")&IF(DATEDIF(C16,B16,"ym")=1," month"," months"),IF(DATEDIF(C16,B16,"m")>=1,DATEDIF(C16,B16,"m")&IF(DATEDIF(C16,B16,"m")=1," month"," months"),DATEDIF(C16,B16,"d")&IF(DATEDIF(C16,B16,"d")=1," day"," days")))) -> 15 days | E16: No | F16: U | G16: Residential Services | H16: Attendance Issues | I16: Sheri McMahan | J16: N/A | K16: DSP | M16: =IFERROR(VLOOKUP(G16,Reference!$I$2:$J$175,2,FALSE()),"Operations") -> Operations
D17: =IF(OR(B17="",C17=""),"",IF(DATEDIF(C17,B17,"y")>=1,DATEDIF(C17,B17,"y")&IF(DATEDIF(C17,B17,"y")=1," year "," years ")&DATEDIF(C17,B17,"ym")&IF(DATEDIF(C17,B17,"ym")=1," month"," months"),IF(DATEDIF(C17,B17,"m")>=1,DATEDIF(C17,B17,"m")&IF(DATEDIF(C17,B17,"m")=1," month"," months"),DATEDIF(C17,B17,"d")&IF(DATEDIF(C17,B17,"d")=1," day"," days")))) | M17: =IFERROR(VLOOKUP(G17,Reference!$I$2:$J$175,2,FALSE()),"Operations") -> Operations
A18: SUBTOTAL: | B18: =COUNTA(A9:A17) -> 8
A20: FEBRUARY 2026
A21: Name | B21: Date of Separation | C21: DOH | D21: Length of Service | E21: Eligible for Rehire | F21: Status | G21: Location | H21: Reason for Leaving | I21: Supervisor | J21: Exit Interview Date | K21: Job | L21: Comments | M21: Department
A22: TaKeiah Biddix | B22: 46061 | C22: 45918 | D22: =IF(OR(B22="",C22=""),"",IF(DATEDIF(C22,B22,"y")>=1,DATEDIF(C22,B22,"y")&IF(DATEDIF(C22,B22,"y")=1," year "," years ")&DATEDIF(C22,B22,"ym")&IF(DATEDIF(C22,B22,"ym")=1," month"," months"),IF(DATEDIF(C22,B22,"m")>=1,DATEDIF(C22,B22,"m")&IF(DATEDIF(C22,B22,"m")=1," month"," months"),DATEDIF(C22,B22,"d")&IF(DATEDIF(C22,B22,"d")=1," day"," days")))) -> 4 months | E22: No | F22: D | G22: 119 Lawton Rd | H22: Job Abandonment | I22: Braylea Wright | J22: N/A | K22: DSP | M22: =IFERROR(VLOOKUP(G22,Reference!$I$2:$J$175,2,FALSE()),"Operations") -> Operations
A23: Ryta Manning | B23: 46056 | C23: 45967 | D23: =IF(OR(B23="",C23=""),"",IF(DATEDIF(C23,B23,"y")>=1,DATEDIF(C23,B23,"y")&IF(DATEDIF(C23,B23,"y")=1," year "," years ")&DATEDIF(C23,B23,"ym")&IF(DATEDIF(C23,B23,"ym")=1," month"," months"),IF(DATEDIF(C23,B23,"m")>=1,DATEDIF(C23,B23,"m")&IF(DATEDIF(C23,B23,"m")=1," month"," months"),DATEDIF(C23,B23,"d")&IF(DATEDIF(C23,B23,"d")=1," day"," days")))) -> 2 months | E23: Yes | F23: U | G23: 107 Ulena Lane | H23: Personal Reasons | I23: Patreese Poore | J23: N/A | K23: DSP | M23: =IFERROR(VLOOKUP(G23,Reference!$I$2:$J$175,2,FALSE()),"Operations") -> Operations
A24: Kaelyn Sibley | B24: 46081 | C24: 45183 | D24: =IF(OR(B24="",C24=""),"",IF(DATEDIF(C24,B24,"y")>=1,DATEDIF(C24,B24,"y")&IF(DATEDIF(C24,B24,"y")=1," year "," years ")&DATEDIF(C24,B24,"ym")&IF(DATEDIF(C24,B24,"ym")=1," month"," months"),IF(DATEDIF(C24,B24,"m")>=1,DATEDIF(C24,B24,"m")&IF(DATEDIF(C24,B24,"m")=1," month"," months"),DATEDIF(C24,B24,"d")&IF(DATEDIF(C24,B24,"d")=1," day"," days")))) -> 2 years 5 months | E24: Yes - Turned in Notice - Not Eligible for rehire | F24: D | G24: 429 W Outer Dr | H24: Better Opportunity | I24: Katlynn Frerichs | J24: TBD | K24: DSP | M24: =IFERROR(VLOOKUP(G24,Reference!$I$2:$J$175,2,FALSE()),"Operations") -> Operations
A25: Robert Price | B25: 46081 | C25: 45203 | D25: =IF(OR(B25="",C25=""),"",IF(DATEDIF(C25,B25,"y")>=1,DATEDIF(C25,B25,"y")&IF(DATEDIF(C25,B25,"y")=1," year "," years ")&DATEDIF(C25,B25,"ym")&IF(DATEDIF(C25,B25,"ym")=1," month"," months"),IF(DATEDIF(C25,B25,"m")>=1,DATEDIF(C25,B25,"m")&IF(DATEDIF(C25,B25,"m")=1," month"," months"),DATEDIF(C25,B25,"d")&IF(DATEDIF(C25,B25,"d")=1," day"," days")))) -> 2 years 4 months | E25: Yes | F25: U | G25: 131 Atlanta | H25: Better Opportunity | I25: Esther Olatoye | J25: TBD | K25: DSP | M25: =IFERROR(VLOOKUP(G25,Reference!$I$2:$J$175,2,FALSE()),"Operations") -> Operations
A26: Heather Lumpkin | B26: 46065 | C26: 41095 | D26: =IF(OR(B26="",C26=""),"",IF(DATEDIF(C26,B26,"y")>=1,DATEDIF(C26,B26,"y")&IF(DATEDIF(C26,B26,"y")=1," year "," years ")&DATEDIF(C26,B26,"ym")&IF(DATEDIF(C26,B26,"ym")=1," month"," months"),IF(DATEDIF(C26,B26,"m")>=1,DATEDIF(C26,B26,"m")&IF(DATEDIF(C26,B26,"m")=1," month"," months"),DATEDIF(C26,B26,"d")&IF(DATEDIF(C26,B26,"d")=1," day"," days")))) -> 13 years 7 months | E26: No | F26: D | G26: 2292 Turnpike | H26: Performance Issues | I26: Katie Jeffers | J26: N/A | K26: DSP | M26: =IFERROR(VLOOKUP(G26,Reference!$I$2:$J$175,2,FALSE()),"Operations") -> Operations
A27: Trinity West | B27: 46069 | C27: 45600 | D27: =IF(OR(B27="",C27=""),"",IF(DATEDIF(C27,B27,"y")>=1,DATEDIF(C27,B27,"y")&IF(DATEDIF(C27,B27,"y")=1," year "," years ")&DATEDIF(C27,B27,"ym")&IF(DATEDIF(C27,B27,"ym")=1," month"," months"),IF(DATEDIF(C27,B27,"m")>=1,DATEDIF(C27,B27,"m")&IF(DATEDIF(C27,B27,"m")=1," month"," months"),DATEDIF(C27,B27,"d")&IF(DATEDIF(C27,B27,"d")=1," day"," days")))) -> 1 year 3 months | E27: No | F27: U | G27: 2290 Turnpike | H27: Resignation | I27: Katie Jeffers | J27: N/A | K27: DSP | M27: =IFERROR(VLOOKUP(G27,Reference!$I$2:$J$175,2,FALSE()),"Operations") -> Operations
A28: Braylea Wright | B28: 46079 | C28: 45152 | D28: =IF(OR(B28="",C28=""),"",IF(DATEDIF(C28,B28,"y")>=1,DATEDIF(C28,B28,"y")&IF(DATEDIF(C28,B28,"y")=1," year "," years ")&DATEDIF(C28,B28,"ym")&IF(DATEDIF(C28,B28,"ym")=1," month"," months"),IF(DATEDIF(C28,B28,"m")>=1,DATEDIF(C28,B28,"m")&IF(DATEDIF(C28,B28,"m")=1," month"," months"),DATEDIF(C28,B28,"d")&IF(DATEDIF(C28,B28,"d")=1," day"," days")))) -> 2 years 6 months | E28: No | F28: U | G28: 2290 Turnpike | H28: Resignation | I28: Katie Jeffers | J28: N/A | K28: HM | M28: =IFERROR(VLOOKUP(G28,Reference!$I$2:$J$175,2,FALSE()),"Operations") -> Operations
A29: Bryan Taylor | B29: 46080 | C29: 44711 | D29: =IF(OR(B29="",C29=""),"",IF(DATEDIF(C29,B29,"y")>=1,DATEDIF(C29,B29,"y")&IF(DATEDIF(C29,B29,"y")=1," year "," years ")&DATEDIF(C29,B29,"ym")&IF(DATEDIF(C29,B29,"ym")=1," month"," months"),IF(DATEDIF(C29,B29,"m")>=1,DATEDIF(C29,B29,"m")&IF(DATEDIF(C29,B29,"m")=1," month"," months"),DATEDIF(C29,B29,"d")&IF(DATEDIF(C29,B29,"d")=1," day"," days")))) -> 3 years 8 months | E29: Yes | F29: U | G29: Finance | H29: Resignation | I29: Jennifer Enderson | J29: N/A | K29: VP | M29: =IFERROR(VLOOKUP(G29,Reference!$I$2:$J$175,2,FALSE()),"Operations") -> Finance
A30: Greta Fair | B30: 46079 | C30: 45761 | D30: =IF(OR(B30="",C30=""),"",IF(DATEDIF(C30,B30,"y")>=1,DATEDIF(C30,B30,"y")&IF(DATEDIF(C30,B30,"y")=1," year "," years ")&DATEDIF(C30,B30,"ym")&IF(DATEDIF(C30,B30,"ym")=1," month"," months"),IF(DATEDIF(C30,B30,"m")>=1,DATEDIF(C30,B30,"m")&IF(DATEDIF(C30,B30,"m")=1," month"," months"),DATEDIF(C30,B30,"d")&IF(DATEDIF(C30,B30,"d")=1," day"," days")))) -> 10 months | E30: No | F30: D | G30: Finance | H30: Termination | I30: Elyse Vanlandingham | J30: N/A | K30: Finance Clerk | M30: =IFERROR(VLOOKUP(G30,Reference!$I$2:$J$175,2,FALSE()),"Operations") -> Finance
A31: Amara Madtes | B31: 46080 | C31: 46062 | D31: =IF(OR(B31="",C31=""),"",IF(DATEDIF(C31,B31,"y")>=1,DATEDIF(C31,B31,"y")&IF(DATEDIF(C31,B31,"y")=1," year "," years ")&DATEDIF(C31,B31,"ym")&IF(DATEDIF(C31,B31,"ym")=1," month"," months"),IF(DATEDIF(C31,B31,"m")>=1,DATEDIF(C31,B31,"m")&IF(DATEDIF(C31,B31,"m")=1," month"," months"),DATEDIF(C31,B31,"d")&IF(DATEDIF(C31,B31,"d")=1," day"," days")))) -> 18 days | E31: No | F31: D | G31: Quality Assurance | H31: Termination | I31: Kristen Otto | J31: N/A | K31: Acreditation Specialist | M31: =IFERROR(VLOOKUP(G31,Reference!$I$2:$J$175,2,FALSE()),"Operations") -> QA
D32: =IF(OR(B32="",C32=""),"",IF(DATEDIF(C32,B32,"y")>=1,DATEDIF(C32,B32,"y")&IF(DATEDIF(C32,B32,"y")=1," year "," years ")&DATEDIF(C32,B32,"ym")&IF(DATEDIF(C32,B32,"ym")=1," month"," months"),IF(DATEDIF(C32,B32,"m")>=1,DATEDIF(C32,B32,"m")&IF(DATEDIF(C32,B32,"m")=1," month"," months"),DATEDIF(C32,B32,"d")&IF(DATEDIF(C32,B32,"d")=1," day"," days")))) | M32: =IFERROR(VLOOKUP(G32,Reference!$I$2:$J$175,2,FALSE()),"Operations") -> Operations
A33: SUBTOTAL: | B33: =COUNTA(A22:A32) -> 10
A35: MARCH 2026
A36: Name | B36: Date of Separation | C36: DOH | D36: Length of Service | E36: Eligible for Rehire | F36: Status | G36: Location | H36: Reason for Leaving | I36: Supervisor | J36: Exit Interview Date | K36: Job | L36: Comments | M36: Department
A37: Ethan Reynolds | B37: 46083 | C37: 45252 | D37: =IF(OR(B37="",C37=""),"",IF(DATEDIF(C37,B37,"y")>=1,DATEDIF(C37,B37,"y")&IF(DATEDIF(C37,B37,"y")=1," year "," years ")&DATEDIF(C37,B37,"ym")&IF(DATEDIF(C37,B37,"ym")=1," month"," months"),IF(DATEDIF(C37,B37,"m")>=1,DATEDIF(C37,B37,"m")&IF(DATEDIF(C37,B37,"m")=1," month"," months"),DATEDIF(C37,B37,"d")&IF(DATEDIF(C37,B37,"d")=1," day"," days")))) -> 2 years 3 months | E37: No | F37: U | G37: 1111 McAdoo | H37: Resignation | I37: Rebecca Smith | J37: TBD | K37: DSP | L37: Rex | M37: =IFERROR(VLOOKUP(G37,Reference!$I$2:$J$175,2,FALSE()),"Operations") -> Operations
A38: Frederick Osborne | B38: 46083 | C38: 38933 | D38: =IF(OR(B38="",C38=""),"",IF(DATEDIF(C38,B38,"y")>=1,DATEDIF(C38,B38,"y")&IF(DATEDIF(C38,B38,"y")=1," year "," years ")&DATEDIF(C38,B38,"ym")&IF(DATEDIF(C38,B38,"ym")=1," month"," months"),IF(DATEDIF(C38,B38,"m")>=1,DATEDIF(C38,B38,"m")&IF(DATEDIF(C38,B38,"m")=1," month"," months"),DATEDIF(C38,B38,"d")&IF(DATEDIF(C38,B38,"d")=1," day"," days")))) -> 19 years 6 months | E38: No | F38: U | G38: 1111 McAdoo | H38: Resignation | I38: Rebecca Smith | J38: TBD | K38: DSP | L38: Rex | M38: =IFERROR(VLOOKUP(G38,Reference!$I$2:$J$175,2,FALSE()),"Operations") -> Operations
A39: Hunter Davis | B39: 46083 | C39: 45943 | D39: =IF(OR(B39="",C39=""),"",IF(DATEDIF(C39,B39,"y")>=1,DATEDIF(C39,B39,"y")&IF(DATEDIF(C39,B39,"y")=1," year "," years ")&DATEDIF(C39,B39,"ym")&IF(DATEDIF(C39,B39,"ym")=1," month"," months"),IF(DATEDIF(C39,B39,"m")>=1,DATEDIF(C39,B39,"m")&IF(DATEDIF(C39,B39,"m")=1," month"," months"),DATEDIF(C39,B39,"d")&IF(DATEDIF(C39,B39,"d")=1," day"," days")))) -> 4 months | E39: No | F39: U | G39: 1111 McAdoo | H39: Resignation | I39: Rebecca Smith | J39: TBD | K39: DSP | L39: Rex | M39: =IFERROR(VLOOKUP(G39,Reference!$I$2:$J$175,2,FALSE()),"Operations") -> Operations
A40: Rebecca Smith | B40: 46084 | C40: 40715 | D40: =IF(OR(B40="",C40=""),"",IF(DATEDIF(C40,B40,"y")>=1,DATEDIF(C40,B40,"y")&IF(DATEDIF(C40,B40,"y")=1," year "," years ")&DATEDIF(C40,B40,"ym")&IF(DATEDIF(C40,B40,"ym")=1," month"," months"),IF(DATEDIF(C40,B40,"m")>=1,DATEDIF(C40,B40,"m")&IF(DATEDIF(C40,B40,"m")=1," month"," months"),DATEDIF(C40,B40,"d")&IF(DATEDIF(C40,B40,"d")=1," day"," days")))) -> 14 years 8 months | E40: Yes | F40: U | G40: 1111 McAdoo | H40: Resignation | I40: Kelly Dustan | J40: TBD | K40: HM | L40: Rex | M40: =IFERROR(VLOOKUP(G40,Reference!$I$2:$J$175,2,FALSE()),"Operations") -> Operations
A41: Tanthya Bigham | B41: 46085 | C41: 46076 | D41: =IF(OR(B41="",C41=""),"",IF(DATEDIF(C41,B41,"y")>=1,DATEDIF(C41,B41,"y")&IF(DATEDIF(C41,B41,"y")=1," year "," years ")&DATEDIF(C41,B41,"ym")&IF(DATEDIF(C41,B41,"ym")=1," month"," months"),IF(DATEDIF(C41,B41,"m")>=1,DATEDIF(C41,B41,"m")&IF(DATEDIF(C41,B41,"m")=1," month"," months"),DATEDIF(C41,B41,"d")&IF(DATEDIF(C41,B41,"d")=1," day"," days")))) -> 9 days | E41: No | F41: U | G41: 813 NW Sapphire | H41: Resignation without Notice | I41: Dustan Kelley | J41: TBD | K41: DSP | M41: =IFERROR(VLOOKUP(G41,Reference!$I$2:$J$175,2,FALSE()),"Operations") -> Operations
A42: Tyreese Langston | B42: 46085 | C42: 45463 | D42: =IF(OR(B42="",C42=""),"",IF(DATEDIF(C42,B42,"y")>=1,DATEDIF(C42,B42,"y")&IF(DATEDIF(C42,B42,"y")=1," year "," years ")&DATEDIF(C42,B42,"ym")&IF(DATEDIF(C42,B42,"ym")=1," month"," months"),IF(DATEDIF(C42,B42,"m")>=1,DATEDIF(C42,B42,"m")&IF(DATEDIF(C42,B42,"m")=1," month"," months"),DATEDIF(C42,B42,"d")&IF(DATEDIF(C42,B42,"d")=1," day"," days")))) -> 1 year 8 months | E42: Yes | F42: U | G42: 1111 McAdoo | H42: Resignation | I42: Rebecca Smith | J42: TBD | K42: DSP | L42: Rex | M42: =IFERROR(VLOOKUP(G42,Reference!$I$2:$J$175,2,FALSE()),"Operations") -> Operations
A43: Dallas Russel | B43: 46086 | C43: 45705 | D43: =IF(OR(B43="",C43=""),"",IF(DATEDIF(C43,B43,"y")>=1,DATEDIF(C43,B43,"y")&IF(DATEDIF(C43,B43,"y")=1," year "," years ")&DATEDIF(C43,B43,"ym")&IF(DATEDIF(C43,B43,"ym")=1," month"," months"),IF(DATEDIF(C43,B43,"m")>=1,DATEDIF(C43,B43,"m")&IF(DATEDIF(C43,B43,"m")=1," month"," months"),DATEDIF(C43,B43,"d")&IF(DATEDIF(C43,B43,"d")=1," day"," days")))) -> 1 year 0 months | E43: Yes | F43: U | G43: Tiffin | H43: Resignation | I43: Sarah Allen | J43: TBD | K43: DSP | M43: =IFERROR(VLOOKUP(G43,Reference!$I$2:$J$175,2,FALSE()),"Operations") -> Operations
A44: Marilyn Drake | B44: 46092 | C44: 45875 | D44: =IF(OR(B44="",C44=""),"",IF(DATEDIF(C44,B44,"y")>=1,DATEDIF(C44,B44,"y")&IF(DATEDIF(C44,B44,"y")=1," year "," years ")&DATEDIF(C44,B44,"ym")&IF(DATEDIF(C44,B44,"ym")=1," month"," months"),IF(DATEDIF(C44,B44,"m")>=1,DATEDIF(C44,B44,"m")&IF(DATEDIF(C44,B44,"m")=1," month"," months"),DATEDIF(C44,B44,"d")&IF(DATEDIF(C44,B44,"d")=1," day"," days")))) -> 7 months | E44: Yes | F44: D | G44: 100 Thelma Road | H44: Resignation | I44: Bethany Quiggle | J44: TBD | K44: DSP | M44: =IFERROR(VLOOKUP(G44,Reference!$I$2:$J$175,2,FALSE()),"Operations") -> Operations
A45: Justin Williams | B45: 46097 | C45: 45621 | D45: =IF(OR(B45="",C45=""),"",IF(DATEDIF(C45,B45,"y")>=1,DATEDIF(C45,B45,"y")&IF(DATEDIF(C45,B45,"y")=1," year "," years ")&DATEDIF(C45,B45,"ym")&IF(DATEDIF(C45,B45,"ym")=1," month"," months"),IF(DATEDIF(C45,B45,"m")>=1,DATEDIF(C45,B45,"m")&IF(DATEDIF(C45,B45,"m")=1," month"," months"),DATEDIF(C45,B45,"d")&IF(DATEDIF(C45,B45,"d")=1," day"," days")))) -> 1 year 3 months | E45: Yes | F45: U | G45: 345 W Outer | H45: Resignation | I45: Andria Cassel | J45: TBD | K45: DSP | M45: =IFERROR(VLOOKUP(G45,Reference!$I$2:$J$175,2,FALSE()),"Operations") -> Operations
...

Sheet FY 2025 (Jan25-Dec25)
A2: EMPLOYEE SEPARATION SUMMARY — FY 2025
A3: January 2025 — December 2025 | Emory Valley Center
A5: Active Employees: | B5: 346 | D5: YTD Separations: | E5: =B39+B73+B107+B141+B175+B209+B243+B277+B311+B345+B379+B413 -> 138 | G5: TOR %: | H5: =IF(B5=0,0,E5/B5) -> 0.39884393
A7: JANUARY 2025
A8: Name | B8: Date of Separation | C8: DOH | D8: Length of Service | E8: Eligible for Rehire | F8: Status | G8: Location | H8: Reason for Leaving | I8: Supervisor | J8: Exit Interview Date | K8: Job | L8: Comments | M8: Department
A9: Tiffany Rose | B9: 45659 | D9: 9 years 11 months | E9: Yes | F9: D | G9: 723 Emory Valley | H9: Better Opportunity | I9: Kim Jeffers-Whitaker | K9: HR | M9: =IFERROR(VLOOKUP(G9,Reference!$I$2:$J$175,2,FALSE()),"Operations") -> Operations
A10: Juliane Rendall | B10: 45667 | D10: 4 years 11 months | E10: No | F10: D | G10: ELC | H10: Termination | I10: Kiersten Wilkerson | K10: Sub/Floater | M10: =IFERROR(VLOOKUP(G10,Reference!$I$2:$J$175,2,FALSE()),"Operations") -> Children Services
A11: Jon Lomax | B11: 45670 | D11: 7 days | E11: No | F11: U | G11: Wadsworth | H11: Other | I11: Kendray Loy-Coon | K11: DSP | M11: =IFERROR(VLOOKUP(G11,Reference!$I$2:$J$175,2,FALSE()),"Operations") -> Operations
A12: Kendra Loy-Coon | B12: 45673 | D12: 7 years 11 months | E12: Yes | F12: D | G12: Four Mile | H12: Resignation | I12: Kasey Foster | K12: DSP | M12: =IFERROR(VLOOKUP(G12,Reference!$I$2:$J$175,2,FALSE()),"Operations") -> Operations
A13: Gabriella Kennedy | B13: 45674 | D13: 11 days | E13: No | F13: U | G13: McAdoo | H13: Personal Reasons | I13: Rebecca Smith | K13: DSP | M13: =IFERROR(VLOOKUP(G13,Reference!$I$2:$J$175,2,FALSE()),"Operations") -> Operations
A14: Jillina Rogers | B14: 45679 | D14: 7 months | E14: Yes | F14: U | G14: Thelma | H14: Personal Reasons | I14: Bethany Quiggle | K14: DSP | M14: =IFERROR(VLOOKUP(G14,Reference!$I$2:$J$175,2,FALSE()),"Operations") -> Operations
A15: Kelci Wiggins | B15: 45677 | D15: 5 months | E15: Yes | F15: D | G15: LLL | H15: Termination | I15: Brittany Webb | K15: Sub/Floater | M15: =IFERROR(VLOOKUP(G15,Reference!$I$2:$J$175,2,FALSE()),"Operations") -> Children Services
A16: Abby Morlock | B16: 45680 | D16: 1 year & 1 month | E16: No | F16: U | G16: Dalton | H16: Personal Reasons | I16: Orian Miller | K16: DSP | M16: =IFERROR(VLOOKUP(G16,Reference!$I$2:$J$175,2,FALSE()),"Operations") -> Operations
A17: Kayla Sullivan | B17: 45659 | D17: 5 months | E17: No | F17: U | G17: Sapphire | H17: Job Abandonment | I17: Melissa Jackson | K17: DSP | M17: =IFERROR(VLOOKUP(G17,Reference!$I$2:$J$175,2,FALSE()),"Operations") -> Operations
A18: Emily West | B18: 45678 | D18: 1 month | E18: Yes | F18: U | G18: 723 Emory Valley | H18: Resignation | I18: Abigail Donald | K18: Other | M18: =IFERROR(VLOOKUP(G18,Reference!$I$2:$J$175,2,FALSE()),"Operations") -> Operations
A19: Jill Battersby | B19: 45684 | D19: 2 years | E19: No | F19: D | G19: 723 Emory Valley | H19: Resignation | I19: Abigail Donald | K19: Other | M19: =IFERROR(VLOOKUP(G19,Reference!$I$2:$J$175,2,FALSE()),"Operations") -> Operations
A20: Paula Winn | B20: 45686 | D20: 1 year | E20: Yes | F20: U | G20: Robert Bunch | H20: Personal Reasons | I20: Jennie England | K20: Other | M20: =IFERROR(VLOOKUP(G20,Reference!$I$2:$J$175,2,FALSE()),"Operations") -> Operations
... A22: Abby Dean | B22: 45688 | D22: 3 months | E22: No | F22: U | G22: ELC | H22: Personal Reasons | I22: Kiersten Wilkerson | K22: Sub/Floater | M22: =IFERROR(VLOOKUP(G22,Reference!$I$2:$J$175,2,FALSE()),"Operations") -> Children Services
D23: =IF(OR(B23="",C23=""),"",IF(DATEDIF(C23,B23,"y")>=1,DATEDIF(C23,B23,"y")&IF(DATEDIF(C23,B23,"y")=1," year "," years ")&DATEDIF(C23,B23,"ym")&IF(DATEDIF(C23,B23,"ym")=1," month"," months"),IF(DATEDIF(C23,B23,"m")>=1,DATEDIF(C23,B23,"m")&IF(DATEDIF(C23,B23,"m")=1," month"," months"),DATEDIF(C23,B23,"d")&IF(DATEDIF(C23,B23,"d")=1," day"," days")))) | M23: =IFERROR(VLOOKUP(G23,Reference!$I$2:$J$175,2,FALSE()),"Operations") -> Operations
D24: =IF(OR(B24="",C24=""),"",IF(DATEDIF(C24,B24,"y")>=1,DATEDIF(C24,B24,"y")&IF(DATEDIF(C24,B24,"y")=1," year "," years ")&DATEDIF(C24,B24,"ym")&IF(DATEDIF(C24,B24,"ym")=1," month"," months"),IF(DATEDIF(C24,B24,"m")>=1,DATEDIF(C24,B24,"m")&IF(DATEDIF(C24,B24,"m")=1," month"," months"),DATEDIF(C24,B24,"d")&IF(DATEDIF(C24,B24,"d")=1," day"," days")))) | M24: =IFERROR(VLOOKUP(G24,Reference!$I$2:$J$175,2,FALSE()),"Operations") -> Operations
D25: =IF(OR(B25="",C25=""),"",IF(DATEDIF(C25,B25,"y")>=1,DATEDIF(C25,B25,"y")&IF(DATEDIF(C25,B25,"y")=1," year "," years ")&DATEDIF(C25,B25,"ym")&IF(DATEDIF(C25,B25,"ym")=1," month"," months"),IF(DATEDIF(C25,B25,"m")>=1,DATEDIF(C25,B25,"m")&IF(DATEDIF(C25,B25,"m")=1," month"," months"),DATEDIF(C25,B25,"d")&IF(DATEDIF(C25,B25,"d")=1," day"," days")))) | M25: =IFERROR(VLOOKUP(G25,Reference!$I$2:$J$175,2,FALSE()),"Operations") -> Operations
D26: =IF(OR(B26="",C26=""),"",IF(DATEDIF(C26,B26,"y")>=1,DATEDIF(C26,B26,"y")&IF(DATEDIF(C26,B26,"y")=1," year "," years ")&DATEDIF(C26,B26,"ym")&IF(DATEDIF(C26,B26,"ym")=1," month"," months"),IF(DATEDIF(C26,B26,"m")>=1,DATEDIF(C26,B26,"m")&IF(DATEDIF(C26,B26,"m")=1," month"," months"),DATEDIF(C26,B26,"d")&IF(DATEDIF(C26,B26,"d")=1," day"," days")))) | M26: =IFERROR(VLOOKUP(G26,Reference!$I$2:$J$175,2,FALSE()),"Operations") -> Operations
